Workbook

Sheet Instructions
B2: How to Use This Model
B3: Update the Inputs sheet only. Every other worksheet is formula-driven and updates automatically.
B5: Worksheet | C5: Instructions
B6: Inputs | C6: This is the only worksheet you edit: facility terms, eligibility tests, concentration limits, the lender's numbers and the four scenarios.
B7: Summary | C7: The borrowing base today, plus a side-by-side comparison of all four scenarios. Use the dropdown to look at one scenario.
B8: Borrowing Base | C8: No manual data entry needed. Walks from the total pool to the borrowing base in four steps.
B9: Loan Tape | C9: The 1,200 hypothetical loans pledged to the warehouse today. The eligibility columns are formulas.
B10: Base / Credit Stress / Market Freeze / Combined Stress | C10: No manual data entry needed. Month-by-month pool, borrowing base, warehouse balance and cash.
B11: Benchmarks | C11: The real data behind the model's pricing, credit and structure, with sources.
B14: What I built
B15: The setup | C15: A non-prime auto lender funds new car loans with a $40M bank warehouse line, then pays the line down every quarter by securitizing the loans.
B16: Borrowing base | C16: Eligibility tests and concentration limits applied to a 1,200-loan tape, then tiered advance rates, following the structure of a real 2025 auto warehouse agreement.
B17: Liquidity | C17: A 12-month projection of the pool, the borrowing base, the warehouse balance and the lender's cash.
B18: Scenarios | C18: Base, a credit stress, a securitization market freeze, and both at once.
B21: Limitations
B22: Pool level | C22: The 12-month projection works on the pool as a whole, not loan by loan, and keeps today's mix of ineligible loans and excess concentrations.
B23: Timing | C23: Defaults, recoveries and payments are monthly and recoveries arrive in the same month as the default.
B24: Data | C24: The loan tape and the facility terms are hypothetical. SOFR, the warehouse margin, recovery rates and the structure come from the real sources on the Benchmarks sheet.

Sheet Summary
B2: Warehouse Lending & Liquidity Model
B3: Summary of the borrowing base today and liquidity over the next 12 months.
B5: Borrowing Base Today
B6: Metric | C6: Value
B7: Total pool | C7: ='Borrowing Base'!C8 -> 28800314
B8: Eligible pool | C8: ='Borrowing Base'!C22 -> 25486061
B9: Excess concentrations | C9: ='Borrowing Base'!$F$40 -> 691202.22
B10: Borrowing base | C10: ='Borrowing Base'!$C$51 -> 20340461
B11: Amount drawn | C11: ='Borrowing Base'!$C$52 -> 19500000
B12: Available to draw | C12: ='Borrowing Base'!$C$53 -> 840460.73
B13: Effective advance on the total pool | C13: ='Borrowing Base'!$C$54 -> 0.70625831
B15: Quick Scenario View
B16: Choose a scenario from the dropdown below.
B17: Scenario | C17: Market Freeze
B18: Lowest cash balance | C18: =INDEX($C$30:$F$30,MATCH($C$17,$C$29:$F$29,0)) -> -37035220
B19: Month of lowest cash | C19: =INDEX($C$31:$F$31,MATCH($C$17,$C$29:$F$29,0)) -> 11
B20: Months below the liquidity covenant | C20: =INDEX($C$33:$F$33,MATCH($C$17,$C$29:$F$29,0)) -> 8
B21: First month below the covenant (0 = never) | C21: =INDEX($C$34:$F$34,MATCH($C$17,$C$29:$F$29,0)) -> 4
B22: Cash at month 12 | C22: =INDEX($C$32:$F$32,MATCH($C$17,$C$29:$F$29,0)) -> 19827806
B23: Months the facility was at its limit | C23: =INDEX($C$35:$F$35,MATCH($C$17,$C$29:$F$29,0)) -> 8
B28: Scenario Comparison (Next 12 Months)
B29: Metric | C29: Base | D29: Credit Stress | E29: Market Freeze | F29: Combined Stress
B30: Lowest cash balance | C30: =MIN(Base!AA$14:AA$25) -> 10065792 | D30: =MIN('Credit Stress'!AA$14:AA$25) -> 2696837.2 | E30: =MIN('Market Freeze'!AA$14:AA$25) -> -37035220 | F30: =MIN('Combined Stress'!AA$14:AA$25) -> -44301825
B31: Month of lowest cash | C31: =INDEX(Base!B$14:B$25,MATCH(MIN(Base!AA$14:AA$25),Base!AA$14:AA$25,0)) -> 2 | D31: =INDEX('Credit Stress'!B$14:B$25,MATCH(MIN('Credit Stress'!AA$14:AA$25),'Credit Stress'!AA$14:AA$25,0)) -> 2 | E31: =INDEX('Market Freeze'!B$14:B$25,MATCH(MIN('Market Freeze'!AA$14:AA$25),'Market Freeze'!AA$14:AA$25,0)) -> 11 | F31: =INDEX('Combined Stress'!B$14:B$25,MATCH(MIN('Combined Stress'!AA$14:AA$25),'Combined Stress'!AA$14:AA$25,0)) -> 11
B32: Cash at month 12 | C32: =Base!AA25 -> 21813352 | D32: ='Credit Stress'!AA25 -> 9419153.7 | E32: ='Market Freeze'!AA25 -> 19827806 | F32: ='Combined Stress'!AA25 -> 641268.09
B33: Months below the liquidity covenant | C33: =SUM(Base!AB$14:AB$25) -> 0 | D33: =SUM('Credit Stress'!AB$14:AB$25) -> 1 | E33: =SUM('Market Freeze'!AB$14:AB$25) -> 8 | F33: =SUM('Combined Stress'!AB$14:AB$25) -> 11
B34: First month below the covenant (0 = never) | C34: =IF(SUM(Base!AB$14:AB$25)=0,0,INDEX(Base!B$14:B$25,MATCH(1,Base!AB$14:AB$25,0))) -> 0 | D34: =IF(SUM('Credit Stress'!AB$14:AB$25)=0,0,INDEX('Credit Stress'!B$14:B$25,MATCH(1,'Credit Stress'!AB$14:AB$25,0))) -> 2 | E34: =IF(SUM('Market Freeze'!AB$14:AB$25)=0,0,INDEX('Market Freeze'!B$14:B$25,MATCH(1,'Market Freeze'!AB$14:AB$25,0))) -> 4 | F34: =IF(SUM('Combined Stress'!AB$14:AB$25)=0,0,INDEX('Combined Stress'!B$14:B$25,MATCH(1,'Combined Stress'!AB$14:AB$25,0))) -> 2
B35: Months the facility was at its limit | C35: =SUM(Base!T$14:T$25) -> 0 | D35: =SUM('Credit Stress'!T$14:T$25) -> 0 | E35: =SUM('Market Freeze'!T$14:T$25) -> 8 | F35: =SUM('Combined Stress'!T$14:T$25) -> 7
B36: Peak warehouse balance | C36: =MAX(Base!S$14:S$25) -> 33118348 | D36: =MAX('Credit Stress'!S$14:S$25) -> 27120058 | E36: =MAX('Market Freeze'!S$14:S$25) -> 40000000 | F36: =MAX('Combined Stress'!S$14:S$25) -> 40000000
B37: Loans securitized over 12 months | C37: =SUM(Base!M$14:M$25) -> 1.3807058e+08 | D37: =SUM('Credit Stress'!M$14:M$25) -> 1.3332895e+08 | E37: =SUM('Market Freeze'!M$14:M$25) -> 1.089969e+08 | F37: =SUM('Combined Stress'!M$14:M$25) -> 96928228
B38: Retained interest in securitizations at month 12 | C38: =Base!AC25 -> 8284234.9 | D38: ='Credit Stress'!AC25 -> 7999736.9 | E38: ='Market Freeze'!AC25 -> 6539813.8 | F38: ='Combined Stress'!AC25 -> 5815693.7

Sheet Inputs
B2: Inputs & Assumptions
B3: This is the only sheet that should be updated manually. Every other worksheet is formula-driven.
B5: Warehouse Facility
B6: Metric | C6: Value | D6: Units | E6: Source / note
B7: Facility commitment | C7: 40000000 | D7: $ | E7: My assumption. Real lines range widely (CPS had three totaling $702.5M; see Benchmarks).
B8: Amount drawn today | C8: 19500000 | D8: $ | E8: My assumption.
B9: SOFR | C9: =Benchmarks!C7 -> 0.0388 | D9: % | E9: SOFR on Oct 7, 2026 (Benchmarks).
B10: Margin over SOFR | C10: =Benchmarks!C9 -> 0.0205 | D10: % | E10: Credit Acceptance's $300M warehouse, July 2025 (Benchmarks).
B11: Unused commitment fee | C11: 0.005 | D11: % / yr | E11: My assumption. Charged on the undrawn part of the line.
B12: Advance rate: near-prime loans | C12: 0.85 | D12: % | E12: My assumption. Real agreements set separate rates by credit tier but redact the numbers.
B13: Advance rate: non-prime loans | C13: 0.75 | D13: % | E13: My assumption.
B14: Near-prime FICO cutoff | C14: 620 | D14: score | E14: Loans at or above this FICO count as near-prime.
B16: Eligibility Criteria
B17: A loan has to pass every test to count toward the borrowing base.
B18: Test | C18: Limit | D18: Units | E18: Source / note
B19: Maximum days past due | C19: 60 | D19: days | E19: The UACC 2025 agreement treats loans more than 61 days late as delinquent (Benchmarks).
B20: Maximum original term | C20: 75 | D20: months | E20: The UACC 2025 agreement caps near-prime terms at 75 months (Benchmarks).
B21: Maximum loan-to-value | C21: 1.5 | D21: % | E21: My assumption.
B22: Minimum FICO | C22: 540 | D22: score | E22: My assumption.
B23: Maximum current balance | C23: 50000 | D23: $ | E23: My assumption.
B25: Concentration Limits
B26: Any balance above these limits (as a % of the eligible pool) is an excess concentration and gets no advance.
B27: Limit | C27: Max share | D27: Units | E27: Source / note
B28: Any single state | C28: 0.2 | D28: % of eligible | E28: State concentration is a standard limit in the UACC 2025 agreement; the 20% level is my assumption.
B29: Non-prime loans | C29: 0.3 | D29: % of eligible | E29: My assumption.
B30: Original term above 72 months | C30: 0.1 | D30: % of eligible | E30: The UACC agreement limits terms over 72 months; the level is my assumption.
B31: Loan-to-value above 125% | C31: 0.15 | D31: % of eligible | E31: My assumption.
B33: Lender (the Company)
B34: Metric | C34: Value | D34: Units | E34: Source / note
B35: Unrestricted cash today | C35: 12000000 | D35: $ | E35: My assumption.
B36: Minimum liquidity covenant | C36: 5000000 | D36: $ | E36: Warehouse lenders require minimum liquidity (CPS 10-K); the $5M level is my assumption.
B37: New loans originated per month | C37: 10000000 | D37: $ | E37: My assumption, roughly 400 loans a month at this pool's average size.
B38: Operating expenses per month | C38: 600000 | D38: $ | E38: My assumption.
B39: Monthly principal paydown (payments + prepayments) | C39: 0.02 | D39: % of pool | E39: My assumption.
B40: Loss severity on defaults | C40: =1-Benchmarks!C14 -> 0.6226 | D40: % | E40: 1 - 2025 subprime auto ABS recovery rate of 37.74% (Benchmarks).
B41: Securitization proceeds | C41: 0.94 | D41: % of pool sold | E41: Bonds sold as a % of the pool, same as my Auto Loan ABS model (Classes A + B + C).
B42: Securitization costs | C42: 0.01 | D42: % of pool sold | E42: My assumption.
B44: Scenarios
B45: Metric | C45: Base | D45: Credit Stress | E45: Market Freeze | F45: Combined Stress | G45: Units | H45: Note
B46: Annual default rate | C46: 0.1 | D46: 0.2 | E46: 0.1 | F46: 0.2 | G46: % | H46: Base is my assumption; stress doubles it.
...

Sheet Borrowing Base
B2: Borrowing Base
B3: How much the bank will lend against today's loan tape. No manual data entry needed.
B5: Step 1: Total Pool
B6: Metric | C6: Value | D6: Units
B7: Loans in the pool | C7: =COUNTA('Loan Tape'!$B$6:$B$1205) -> 1200 | D7: loans
B8: Total pool balance | C8: =SUM('Loan Tape'!$I$6:$I$1205) -> 28800314 | D8: $
B9: Weighted average APR | C9: =SUMPRODUCT('Loan Tape'!$E$6:$E$1205,'Loan Tape'!$I$6:$I$1205)/C8 -> 0.20778802 | D9: %
B10: Weighted average FICO | C10: =SUMPRODUCT('Loan Tape'!$D$6:$D$1205,'Loan Tape'!$I$6:$I$1205)/C8 -> 645.38931 | D10: score
B12: Step 2: Remove Ineligible Loans
B13: A loan that fails more than one test is counted under each test it fails, so the reasons can add up to more than the total.
B14: Reason | C14: Balance | D14: % of pool
B15: More than 60 days past due | C15: =SUMIFS('Loan Tape'!$I$6:$I$1205,'Loan Tape'!$M$6:$M$1205,0) -> 905410.7 | D15: =C15/$C$8 -> 0.031437529
B16: Original term too long | C16: =SUMIFS('Loan Tape'!$I$6:$I$1205,'Loan Tape'!$N$6:$N$1205,0) -> 1377851.6 | D16: =C16/$C$8 -> 0.047841549
B17: Loan-to-value too high | C17: =SUMIFS('Loan Tape'!$I$6:$I$1205,'Loan Tape'!$O$6:$O$1205,0) -> 20940.17 | D17: =C17/$C$8 -> 0.00072708132
B18: FICO too low | C18: =SUMIFS('Loan Tape'!$I$6:$I$1205,'Loan Tape'!$P$6:$P$1205,0) -> 603065.69 | D18: =C18/$C$8 -> 0.020939553
B19: Balance too large | C19: =SUMIFS('Loan Tape'!$I$6:$I$1205,'Loan Tape'!$Q$6:$Q$1205,0) -> 499925.28 | D19: =C19/$C$8 -> 0.017358328
B20: Total ineligible | C20: =C8-C22 -> 3314252.4 | D20: =C20/$C$8 -> 0.11507695
B22: Eligible pool | C22: =SUM('Loan Tape'!$S$6:$S$1205) -> 25486061 | D22: =C22/$C$8 -> 0.88492305
B24: Step 3: Concentration Limits
B25: Excess = balance above the limit. These are checked against the eligible pool.
B26: Limit | C26: Eligible balance | D26: Actual share | E26: Max share | F26: Excess
B27: State: TX | C27: =SUMIFS('Loan Tape'!$S$6:$S$1205,'Loan Tape'!$C$6:$C$1205,"TX") -> 5788414.5 | D27: =C27/$C$22 -> 0.22712079 | E27: =Inputs!$C$28 -> 0.2 | F27: =MAX(0,C27-E27*$C$22) -> 691202.22
B28: State: CA | C28: =SUMIFS('Loan Tape'!$S$6:$S$1205,'Loan Tape'!$C$6:$C$1205,"CA") -> 3911146.8 | D28: =C28/$C$22 -> 0.15346219 | E28: =Inputs!$C$28 -> 0.2 | F28: =MAX(0,C28-E28*$C$22) -> 0
B29: State: FL | C29: =SUMIFS('Loan Tape'!$S$6:$S$1205,'Loan Tape'!$C$6:$C$1205,"FL") -> 2997151.3 | D29: =C29/$C$22 -> 0.11759963 | E29: =Inputs!$C$28 -> 0.2 | F29: =MAX(0,C29-E29*$C$22) -> 0
B30: State: GA | C30: =SUMIFS('Loan Tape'!$S$6:$S$1205,'Loan Tape'!$C$6:$C$1205,"GA") -> 2786819.3 | D30: =C30/$C$22 -> 0.1093468 | E30: =Inputs!$C$28 -> 0.2 | F30: =MAX(0,C30-E30*$C$22) -> 0
B31: State: NC | C31: =SUMIFS('Loan Tape'!$S$6:$S$1205,'Loan Tape'!$C$6:$C$1205,"NC") -> 2028010.8 | D31: =C31/$C$22 -> 0.079573333 | E31: =Inputs!$C$28 -> 0.2 | F31: =MAX(0,C31-E31*$C$22) -> 0
B32: State: AZ | C32: =SUMIFS('Loan Tape'!$S$6:$S$1205,'Loan Tape'!$C$6:$C$1205,"AZ") -> 1994053.3 | D32: =C32/$C$22 -> 0.078240938 | E32: =Inputs!$C$28 -> 0.2 | F32: =MAX(0,C32-E32*$C$22) -> 0
B33: State: IL | C33: =SUMIFS('Loan Tape'!$S$6:$S$1205,'Loan Tape'!$C$6:$C$1205,"IL") -> 1720538 | D33: =C33/$C$22 -> 0.067508979 | E33: =Inputs!$C$28 -> 0.2 | F33: =MAX(0,C33-E33*$C$22) -> 0
B34: State: OH | C34: =SUMIFS('Loan Tape'!$S$6:$S$1205,'Loan Tape'!$C$6:$C$1205,"OH") -> 1547427.3 | D34: =C34/$C$22 -> 0.060716611 | E34: =Inputs!$C$28 -> 0.2 | F34: =MAX(0,C34-E34*$C$22) -> 0
B35: State: PA | C35: =SUMIFS('Loan Tape'!$S$6:$S$1205,'Loan Tape'!$C$6:$C$1205,"PA") -> 1549349.8 | D35: =C35/$C$22 -> 0.060792048 | E35: =Inputs!$C$28 -> 0.2 | F35: =MAX(0,C35-E35*$C$22) -> 0
B36: State: NV | C36: =SUMIFS('Loan Tape'!$S$6:$S$1205,'Loan Tape'!$C$6:$C$1205,"NV") -> 1163150.1 | D36: =C36/$C$22 -> 0.045638675 | E36: =Inputs!$C$28 -> 0.2 | F36: =MAX(0,C36-E36*$C$22) -> 0
B37: Non-prime loans | C37: =SUMIFS('Loan Tape'!$S$6:$S$1205,'Loan Tape'!$L$6:$L$1205,"Non-prime") -> 7556635.4 | D37: =C37/$C$22 -> 0.29650072 | E37: =Inputs!$C$29 -> 0.3 | F37: =MAX(0,C37-E37*$C$22) -> 0
B38: Original term above 72 months | C38: =SUMIFS('Loan Tape'!$S$6:$S$1205,'Loan Tape'!$T$6:$T$1205,1) -> 2321437.2 | D38: =C38/$C$22 -> 0.091086542 | E38: =Inputs!$C$30 -> 0.1 | F38: =MAX(0,C38-E38*$C$22) -> 0
B39: Loan-to-value above 125% | C39: =SUMIFS('Loan Tape'!$S$6:$S$1205,'Loan Tape'!$U$6:$U$1205,1) -> 3716307.6 | D39: =C39/$C$22 -> 0.14581726 | E39: =Inputs!$C$31 -> 0.15 | F39: =MAX(0,C39-E39*$C$22) -> 0
B40: Total excess concentration | F40: =SUM(F27:F39) -> 691202.22
B42: Step 4: Borrowing Base and Availability
B43: Metric | C43: Value | D43: Units | F43: How it's calculated
B44: Eligible pool | C44: =C22 -> 25486061 | D44: $ | F44: From step 2
B45: Less: excess concentrations | C45: =-$F$40 -> -691202.22 | D45: $ | F45: From step 3
B46: Adjusted eligible pool | C46: =C44+C45 -> 24794859 | D46: $ | F46: Eligible pool minus excess
...

Sheet Loan Tape
B2: Loan Tape
B3: Hypothetical receivables currently pledged to the warehouse. Columns L onward are formulas.
B5: Loan ID | C5: State | D5: FICO | E5: APR | F5: Original term | G5: Months seasoned | H5: Original balance | I5: Current balance | J5: LTV | K5: Days past due | L5: Credit tier | M5: Passes days past due | N5: Passes term | O5: Passes LTV | P5: Passes FICO | Q5: Passes balance | R5: Eligible | S5: Eligible balance | T5: Term over 72 | U5: LTV over 125%
B6: WL-00001 | C6: TX | D6: 625 | E6: 0.2233 | F6: 72 | G6: 10 | H6: 21820 | I6: 20226.03 | J6: 1.183 | K6: 0 | L6: =IF(D6>=Inputs!$C$14,"Near-prime","Non-prime") -> Near-prime | M6: =IF(K6<=Inputs!$C$19,1,0) -> 1 | N6: =IF(F6<=Inputs!$C$20,1,0) -> 1 | O6: =IF(J6<=Inputs!$C$21,1,0) -> 1 | P6: =IF(D6>=Inputs!$C$22,1,0) -> 1 | Q6: =IF(I6<=Inputs!$C$23,1,0) -> 1 | R6: =M6*N6*O6*P6*Q6 -> 1 | S6: =I6*R6 -> 20226.03 | T6: =IF(F6>72,1,0) -> 0 | U6: =IF(J6>1.25,1,0) -> 0
B7: WL-00002 | C7: AZ | D7: 621 | E7: 0.2132 | F7: 60 | G7: 10 | H7: 17700 | I7: 15883.82 | J7: 1.04 | K7: 0 | L7: =IF(D7>=Inputs!$C$14,"Near-prime","Non-prime") -> Near-prime | M7: =IF(K7<=Inputs!$C$19,1,0) -> 1 | N7: =IF(F7<=Inputs!$C$20,1,0) -> 1 | O7: =IF(J7<=Inputs!$C$21,1,0) -> 1 | P7: =IF(D7>=Inputs!$C$22,1,0) -> 1 | Q7: =IF(I7<=Inputs!$C$23,1,0) -> 1 | R7: =M7*N7*O7*P7*Q7 -> 1 | S7: =I7*R7 -> 15883.82 | T7: =IF(F7>72,1,0) -> 0 | U7: =IF(J7>1.25,1,0) -> 0
B8: WL-00003 | C8: FL | D8: 565 | E8: 0.2236 | F8: 72 | G8: 6 | H8: 25440 | I8: 24367.36 | J8: 1.106 | K8: 0 | L8: =IF(D8>=Inputs!$C$14,"Near-prime","Non-prime") -> Non-prime | M8: =IF(K8<=Inputs!$C$19,1,0) -> 1 | N8: =IF(F8<=Inputs!$C$20,1,0) -> 1 | O8: =IF(J8<=Inputs!$C$21,1,0) -> 1 | P8: =IF(D8>=Inputs!$C$22,1,0) -> 1 | Q8: =IF(I8<=Inputs!$C$23,1,0) -> 1 | R8: =M8*N8*O8*P8*Q8 -> 1 | S8: =I8*R8 -> 24367.36 | T8: =IF(F8>72,1,0) -> 0 | U8: =IF(J8>1.25,1,0) -> 0
B9: WL-00004 | C9: CA | D9: 626 | E9: 0.2109 | F9: 72 | G9: 7 | H9: 37380 | I9: 35445.12 | J9: 0.926 | K9: 15 | L9: =IF(D9>=Inputs!$C$14,"Near-prime","Non-prime") -> Near-prime | M9: =IF(K9<=Inputs!$C$19,1,0) -> 1 | N9: =IF(F9<=Inputs!$C$20,1,0) -> 1 | O9: =IF(J9<=Inputs!$C$21,1,0) -> 1 | P9: =IF(D9>=Inputs!$C$22,1,0) -> 1 | Q9: =IF(I9<=Inputs!$C$23,1,0) -> 1 | R9: =M9*N9*O9*P9*Q9 -> 1 | S9: =I9*R9 -> 35445.12 | T9: =IF(F9>72,1,0) -> 0 | U9: =IF(J9>1.25,1,0) -> 0
B10: WL-00005 | C10: CA | D10: 667 | E10: 0.2182 | F10: 72 | G10: 4 | H10: 22800 | I10: 22159.34 | J10: 1.196 | K10: 0 | L10: =IF(D10>=Inputs!$C$14,"Near-prime","Non-prime") -> Near-prime | M10: =IF(K10<=Inputs!$C$19,1,0) -> 1 | N10: =IF(F10<=Inputs!$C$20,1,0) -> 1 | O10: =IF(J10<=Inputs!$C$21,1,0) -> 1 | P10: =IF(D10>=Inputs!$C$22,1,0) -> 1 | Q10: =IF(I10<=Inputs!$C$23,1,0) -> 1 | R10: =M10*N10*O10*P10*Q10 -> 1 | S10: =I10*R10 -> 22159.34 | T10: =IF(F10>72,1,0) -> 0 | U10: =IF(J10>1.25,1,0) -> 0
B11: WL-00006 | C11: OH | D11: 585 | E11: 0.2062 | F11: 48 | G11: 10 | H11: 36830 | I11: 31424.14 | J11: 1.085 | K11: 0 | L11: =IF(D11>=Inputs!$C$14,"Near-prime","Non-prime") -> Non-prime | M11: =IF(K11<=Inputs!$C$19,1,0) -> 1 | N11: =IF(F11<=Inputs!$C$20,1,0) -> 1 | O11: =IF(J11<=Inputs!$C$21,1,0) -> 1 | P11: =IF(D11>=Inputs!$C$22,1,0) -> 1 | Q11: =IF(I11<=Inputs!$C$23,1,0) -> 1 | R11: =M11*N11*O11*P11*Q11 -> 1 | S11: =I11*R11 -> 31424.14 | T11: =IF(F11>72,1,0) -> 0 | U11: =IF(J11>1.25,1,0) -> 0
B12: WL-00007 | C12: IL | D12: 658 | E12: 0.2086 | F12: 72 | G12: 2 | H12: 17590 | I12: 17339.09 | J12: 1.066 | K12: 0 | L12: =IF(D12>=Inputs!$C$14,"Near-prime","Non-prime") -> Near-prime | M12: =IF(K12<=Inputs!$C$19,1,0) -> 1 | N12: =IF(F12<=Inputs!$C$20,1,0) -> 1 | O12: =IF(J12<=Inputs!$C$21,1,0) -> 1 | P12: =IF(D12>=Inputs!$C$22,1,0) -> 1 | Q12: =IF(I12<=Inputs!$C$23,1,0) -> 1 | R12: =M12*N12*O12*P12*Q12 -> 1 | S12: =I12*R12 -> 17339.09 | T12: =IF(F12>72,1,0) -> 0 | U12: =IF(J12>1.25,1,0) -> 0
B13: WL-00008 | C13: TX | D13: 539 | E13: 0.2599 | F13: 60 | G13: 0 | H13: 25610 | I13: 25610 | J13: 1.296 | K13: 0 | L13: =IF(D13>=Inputs!$C$14,"Near-prime","Non-prime") -> Non-prime | M13: =IF(K13<=Inputs!$C$19,1,0) -> 1 | N13: =IF(F13<=Inputs!$C$20,1,0) -> 1 | O13: =IF(J13<=Inputs!$C$21,1,0) -> 1 | P13: =IF(D13>=Inputs!$C$22,1,0) -> 0 | Q13: =IF(I13<=Inputs!$C$23,1,0) -> 1 | R13: =M13*N13*O13*P13*Q13 -> 0 | S13: =I13*R13 -> 0 | T13: =IF(F13>72,1,0) -> 0 | U13: =IF(J13>1.25,1,0) -> 1
B14: WL-00009 | C14: AZ | D14: 671 | E14: 0.2025 | F14: 60 | G14: 4 | H14: 29970 | I14: 28770.24 | J14: 1.172 | K14: 0 | L14: =IF(D14>=Inputs!$C$14,"Near-prime","Non-prime") -> Near-prime | M14: =IF(K14<=Inputs!$C$19,1,0) -> 1 | N14: =IF(F14<=Inputs!$C$20,1,0) -> 1 | O14: =IF(J14<=Inputs!$C$21,1,0) -> 1 | P14: =IF(D14>=Inputs!$C$22,1,0) -> 1 | Q14: =IF(I14<=Inputs!$C$23,1,0) -> 1 | R14: =M14*N14*O14*P14*Q14 -> 1 | S14: =I14*R14 -> 28770.24 | T14: =IF(F14>72,1,0) -> 0 | U14: =IF(J14>1.25,1,0) -> 0
B15: WL-00010 | C15: CA | D15: 615 | E15: 0.2245 | F15: 60 | G15: 3 | H15: 28490 | I15: 27691.74 | J15: 1.206 | K15: 0 | L15: =IF(D15>=Inputs!$C$14,"Near-prime","Non-prime") -> Non-prime | M15: =IF(K15<=Inputs!$C$19,1,0) -> 1 | N15: =IF(F15<=Inputs!$C$20,1,0) -> 1 | O15: =IF(J15<=Inputs!$C$21,1,0) -> 1 | P15: =IF(D15>=Inputs!$C$22,1,0) -> 1 | Q15: =IF(I15<=Inputs!$C$23,1,0) -> 1 | R15: =M15*N15*O15*P15*Q15 -> 1 | S15: =I15*R15 -> 27691.74 | T15: =IF(F15>72,1,0) -> 0 | U15: =IF(J15>1.25,1,0) -> 0
B16: WL-00011 | C16: NV | D16: 575 | E16: 0.2151 | F16: 72 | G16: 5 | H16: 22320 | I16: 21520.57 | J16: 1.065 | K16: 15 | L16: =IF(D16>=Inputs!$C$14,"Near-prime","Non-prime") -> Non-prime | M16: =IF(K16<=Inputs!$C$19,1,0) -> 1 | N16: =IF(F16<=Inputs!$C$20,1,0) -> 1 | O16: =IF(J16<=Inputs!$C$21,1,0) -> 1 | P16: =IF(D16>=Inputs!$C$22,1,0) -> 1 | Q16: =IF(I16<=Inputs!$C$23,1,0) -> 1 | R16: =M16*N16*O16*P16*Q16 -> 1 | S16: =I16*R16 -> 21520.57 | T16: =IF(F16>72,1,0) -> 0 | U16: =IF(J16>1.25,1,0) -> 0
B17: WL-00012 | C17: IL | D17: 702 | E17: 0.1892 | F17: 72 | G17: 1 | H17: 12080 | I17: 11988.62 | J17: 1.012 | K17: 0 | L17: =IF(D17>=Inputs!$C$14,"Near-prime","Non-prime") -> Near-prime | M17: =IF(K17<=Inputs!$C$19,1,0) -> 1 | N17: =IF(F17<=Inputs!$C$20,1,0) -> 1 | O17: =IF(J17<=Inputs!$C$21,1,0) -> 1 | P17: =IF(D17>=Inputs!$C$22,1,0) -> 1 | Q17: =IF(I17<=Inputs!$C$23,1,0) -> 1 | R17: =M17*N17*O17*P17*Q17 -> 1 | S17: =I17*R17 -> 11988.62 | T17: =IF(F17>72,1,0) -> 0 | U17: =IF(J17>1.25,1,0) -> 0
... B1205: WL-01200 | C1205: TX | D1205: 630 | E1205: 0.2187 | F1205: 72 | G1205: 9 | H1205: 22430 | I1205: 20947.62 | J1205: 0.787 | K1205: 0 | L1205: =IF(D1205>=Inputs!$C$14,"Near-prime","Non-prime") -> Near-prime | M1205: =IF(K1205<=Inputs!$C$19,1,0) -> 1 | N1205: =IF(F1205<=Inputs!$C$20,1,0) -> 1 | O1205: =IF(J1205<=Inputs!$C$21,1,0) -> 1 | P1205: =IF(D1205>=Inputs!$C$22,1,0) -> 1 | Q1205: =IF(I1205<=Inputs!$C$23,1,0) -> 1 | R1205: =M1205*N1205*O1205*P1205*Q1205 -> 1 | S1205: =I1205*R1205 -> 20947.62 | T1205: =IF(F1205>72,1,0) -> 0 | U1205: =IF(J1205>1.25,1,0) -> 0

Sheet Base
B2: Base: 12-Month Liquidity Projection
B3: No manual data entry needed. Month 0 is today.
B5: Scenario Inputs
B6: Metric | C6: Value | D6: Units
B7: Annual default rate | C7: =Inputs!C46 -> 0.1 | D7: %
B8: Monthly default rate: 1 - (1 - annual)^(1/12) | C8: =1-(1-C7)^(1/12) -> 0.008741611 | D8: %
B9: Share more than 60 days late | C9: =Inputs!C47 -> 0.031437529 | D9: %
B10: Advance rate after any cut | C10: ='Borrowing Base'!$C$48-Inputs!C48 -> 0.82034993 | D10: %
B12: Month | C12: Beginning pool | D12: Defaults | E12: Recoveries | F12: Principal collected | G12: Interest collected | H12: New loans | I12: Pool before sale | J12: Late (ineligible) | K12: Other ineligible | L12: Eligible before sale | M12: Securitized | N12: Ending pool | O12: Eligible after sale | P12: Advance rate | Q12: Borrowing base | R12: Warehouse beginning | S12: Warehouse ending | T12: Facility at limit | U12: Warehouse interest | V12: Unused fee | W12: Operating expenses | X12: Securitization cash | Y12: Cash from past deals | Z12: Beginning cash | AA12: Ending cash | AB12: Covenant breach | AC12: Retained interest
B13: 0 | N13: ='Borrowing Base'!C8 -> 28800314 | S13: =Inputs!$C$8 -> 19500000 | AA13: =Inputs!$C$35 -> 12000000 | AC13: 0
B14: =B13+1 -> 1 | C14: =N13 -> 28800314 | D14: =C14*$C$8 -> 251761.14 | E14: =D14*(1-Inputs!$C$40) -> 95014.653 | F14: =(C14-D14)*Inputs!$C$39 -> 570971.05 | G14: =(C14-D14)*'Borrowing Base'!$C$9/12 -> 494337.27 | H14: =Inputs!$C$37 -> 10000000 | I14: =C14-D14-F14+H14 -> 37977581 | J14: =I14*$C$9 -> 1193921.3 | K14: =I14*'Borrowing Base'!$C$59 -> 3176423.1 | L14: =I14-J14-K14 -> 33607237 | M14: =L14*0 -> 0 | N14: =I14-M14 -> 37977581 | O14: =L14-M14 -> 33607237 | P14: =$C$10 -> 0.82034993 | Q14: =MIN(Inputs!$C$7,P14*O14*(1-'Borrowing Base'!$C$60)) -> 26821982 | R14: =S13 -> 19500000 | S14: =Q14 -> 26821982 | T14: =IF(P14*O14*(1-'Borrowing Base'!$C$60)>Inputs!$C$7,1,0) -> 0 | U14: =R14*(Inputs!$C$9+Inputs!$C$10)/12 -> 96362.5 | V14: =MAX(0,Inputs!$C$7-R14)*Inputs!$C$11/12 -> 8541.6667 | W14: =Inputs!$C$38 -> 600000 | X14: =M14*(Inputs!$C$41-Inputs!$C$42) -> 0 | Y14: =Inputs!C49 -> 1600000 | Z14: =AA13 -> 12000000 | AA14: =Z14-H14+F14+G14+E14-U14-V14-W14+(S14-R14)+X14+Y14 -> 11377401 | AB14: =IF(AA14<Inputs!$C$36,1,0) -> 0 | AC14: =AC13+M14*(1-Inputs!$C$41) -> 0
B15: =B14+1 -> 2 | C15: =N14 -> 37977581 | D15: =C15*$C$8 -> 331985.24 | E15: =D15*(1-Inputs!$C$40) -> 125291.23 | F15: =(C15-D15)*Inputs!$C$39 -> 752911.92 | G15: =(C15-D15)*'Borrowing Base'!$C$9/12 -> 651858.67 | H15: =Inputs!$C$37 -> 10000000 | I15: =C15-D15-F15+H15 -> 46892684 | J15: =I15*$C$9 -> 1474190.1 | K15: =I15*'Borrowing Base'!$C$59 -> 3922077.2 | L15: =I15-J15-K15 -> 41496417 | M15: =L15*0 -> 0 | N15: =I15-M15 -> 46892684 | O15: =L15-M15 -> 41496417 | P15: =$C$10 -> 0.82034993 | Q15: =MIN(Inputs!$C$7,P15*O15*(1-'Borrowing Base'!$C$60)) -> 33118348 | R15: =S14 -> 26821982 | S15: =Q15 -> 33118348 | T15: =IF(P15*O15*(1-'Borrowing Base'!$C$60)>Inputs!$C$7,1,0) -> 0 | U15: =R15*(Inputs!$C$9+Inputs!$C$10)/12 -> 132545.3 | V15: =MAX(0,Inputs!$C$7-R15)*Inputs!$C$11/12 -> 5490.8407 | W15: =Inputs!$C$38 -> 600000 | X15: =M15*(Inputs!$C$41-Inputs!$C$42) -> 0 | Y15: =Inputs!C49 -> 1600000 | Z15: =AA14 -> 11377401 | AA15: =Z15-H15+F15+G15+E15-U15-V15-W15+(S15-R15)+X15+Y15 -> 10065792 | AB15: =IF(AA15<Inputs!$C$36,1,0) -> 0 | AC15: =AC14+M15*(1-Inputs!$C$41) -> 0
B16: =B15+1 -> 3 | C16: =N15 -> 46892684 | D16: =C16*$C$8 -> 409917.6 | E16: =D16*(1-Inputs!$C$40) -> 154702.9 | F16: =(C16-D16)*Inputs!$C$39 -> 929655.33 | G16: =(C16-D16)*'Borrowing Base'!$C$9/12 -> 804880.18 | H16: =Inputs!$C$37 -> 10000000 | I16: =C16-D16-F16+H16 -> 55553111 | J16: =I16*$C$9 -> 1746452.6 | K16: =I16*'Borrowing Base'!$C$59 -> 4646430.3 | L16: =I16-J16-K16 -> 49160228 | M16: =L16*Inputs!C50 -> 49160228 | N16: =I16-M16 -> 6392882.9 | O16: =L16-M16 -> 0 | P16: =$C$10 -> 0.82034993 | Q16: =MIN(Inputs!$C$7,P16*O16*(1-'Borrowing Base'!$C$60)) -> 0 | R16: =S15 -> 33118348 | S16: =Q16 -> 0 | T16: =IF(P16*O16*(1-'Borrowing Base'!$C$60)>Inputs!$C$7,1,0) -> 0 | U16: =R16*(Inputs!$C$9+Inputs!$C$10)/12 -> 163659.84 | V16: =MAX(0,Inputs!$C$7-R16)*Inputs!$C$11/12 -> 2867.3551 | W16: =Inputs!$C$38 -> 600000 | X16: =M16*(Inputs!$C$41-Inputs!$C$42) -> 45719012 | Y16: =Inputs!C49 -> 1600000 | Z16: =AA15 -> 10065792 | AA16: =Z16-H16+F16+G16+E16-U16-V16-W16+(S16-R16)+X16+Y16 -> 15389168 | AB16: =IF(AA16<Inputs!$C$36,1,0) -> 0 | AC16: =AC15+M16*(1-Inputs!$C$41) -> 2949613.7
B17: =B16+1 -> 4 | C17: =N16 -> 6392882.9 | D17: =C17*$C$8 -> 55884.095 | E17: =D17*(1-Inputs!$C$40) -> 21090.657 | F17: =(C17-D17)*Inputs!$C$39 -> 126739.98 | G17: =(C17-D17)*'Borrowing Base'!$C$9/12 -> 109729.37 | H17: =Inputs!$C$37 -> 10000000 | I17: =C17-D17-F17+H17 -> 16210259 | J17: =I17*$C$9 -> 509610.49 | K17: =I17*'Borrowing Base'!$C$59 -> 1355816.7 | L17: =I17-J17-K17 -> 14344832 | M17: =L17*0 -> 0 | N17: =I17-M17 -> 16210259 | O17: =L17-M17 -> 14344832 | P17: =$C$10 -> 0.82034993 | Q17: =MIN(Inputs!$C$7,P17*O17*(1-'Borrowing Base'!$C$60)) -> 11448630 | R17: =S16 -> 0 | S17: =Q17 -> 11448630 | T17: =IF(P17*O17*(1-'Borrowing Base'!$C$60)>Inputs!$C$7,1,0) -> 0 | U17: =R17*(Inputs!$C$9+Inputs!$C$10)/12 -> 0 | V17: =MAX(0,Inputs!$C$7-R17)*Inputs!$C$11/12 -> 16666.667 | W17: =Inputs!$C$38 -> 600000 | X17: =M17*(Inputs!$C$41-Inputs!$C$42) -> 0 | Y17: =Inputs!C49 -> 1600000 | Z17: =AA16 -> 15389168 | AA17: =Z17-H17+F17+G17+E17-U17-V17-W17+(S17-R17)+X17+Y17 -> 18078691 | AB17: =IF(AA17<Inputs!$C$36,1,0) -> 0 | AC17: =AC16+M17*(1-Inputs!$C$41) -> 2949613.7
B18: =B17+1 -> 5 | C18: =N17 -> 16210259 | D18: =C18*$C$8 -> 141703.78 | E18: =D18*(1-Inputs!$C$40) -> 53479.005 | F18: =(C18-D18)*Inputs!$C$39 -> 321371.1 | G18: =(C18-D18)*'Borrowing Base'!$C$9/12 -> 278237.77 | H18: =Inputs!$C$37 -> 10000000 | I18: =C18-D18-F18+H18 -> 25747184 | J18: =I18*$C$9 -> 809427.85 | K18: =I18*'Borrowing Base'!$C$59 -> 2153479.7 | L18: =I18-J18-K18 -> 22784276 | M18: =L18*0 -> 0 | N18: =I18-M18 -> 25747184 | O18: =L18-M18 -> 22784276 | P18: =$C$10 -> 0.82034993 | Q18: =MIN(Inputs!$C$7,P18*O18*(1-'Borrowing Base'!$C$60)) -> 18184163 | R18: =S17 -> 11448630 | S18: =Q18 -> 18184163 | T18: =IF(P18*O18*(1-'Borrowing Base'!$C$60)>Inputs!$C$7,1,0) -> 0 | U18: =R18*(Inputs!$C$9+Inputs!$C$10)/12 -> 56575.313 | V18: =MAX(0,Inputs!$C$7-R18)*Inputs!$C$11/12 -> 11896.404 | W18: =Inputs!$C$38 -> 600000 | X18: =M18*(Inputs!$C$41-Inputs!$C$42) -> 0 | Y18: =Inputs!C49 -> 1600000 | Z18: =AA17 -> 18078691 | AA18: =Z18-H18+F18+G18+E18-U18-V18-W18+(S18-R18)+X18+Y18 -> 16398840 | AB18: =IF(AA18<Inputs!$C$36,1,0) -> 0 | AC18: =AC17+M18*(1-Inputs!$C$41) -> 2949613.7
B19: =B18+1 -> 6 | C19: =N18 -> 25747184 | D19: =C19*$C$8 -> 225071.86 | E19: =D19*(1-Inputs!$C$40) -> 84942.122 | F19: =(C19-D19)*Inputs!$C$39 -> 510442.24 | G19: =(C19-D19)*'Borrowing Base'!$C$9/12 -> 441932.44 | H19: =Inputs!$C$37 -> 10000000 | I19: =C19-D19-F19+H19 -> 35011670 | J19: =I19*$C$9 -> 1100680.4 | K19: =I19*'Borrowing Base'!$C$59 -> 2928355.9 | L19: =I19-J19-K19 -> 30982633 | M19: =L19*Inputs!C51 -> 30982633 | N19: =I19-M19 -> 4029036.3 | O19: =L19-M19 -> 0 | P19: =$C$10 -> 0.82034993 | Q19: =MIN(Inputs!$C$7,P19*O19*(1-'Borrowing Base'!$C$60)) -> 0 | R19: =S18 -> 18184163 | S19: =Q19 -> 0 | T19: =IF(P19*O19*(1-'Borrowing Base'!$C$60)>Inputs!$C$7,1,0) -> 0 | U19: =R19*(Inputs!$C$9+Inputs!$C$10)/12 -> 89860.07 | V19: =MAX(0,Inputs!$C$7-R19)*Inputs!$C$11/12 -> 9089.9323 | W19: =Inputs!$C$38 -> 600000 | X19: =M19*(Inputs!$C$41-Inputs!$C$42) -> 28813849 | Y19: =Inputs!C49 -> 1600000 | Z19: =AA18 -> 16398840 | AA19: =Z19-H19+F19+G19+E19-U19-V19-W19+(S19-R19)+X19+Y19 -> 18966894 | AB19: =IF(AA19<Inputs!$C$36,1,0) -> 0 | AC19: =AC18+M19*(1-Inputs!$C$41) -> 4808571.7
B20: =B19+1 -> 7 | C20: =N19 -> 4029036.3 | D20: =C20*$C$8 -> 35220.268 | E20: =D20*(1-Inputs!$C$40) -> 13292.129 | F20: =(C20-D20)*Inputs!$C$39 -> 79876.321 | G20: =(C20-D20)*'Borrowing Base'!$C$9/12 -> 69155.596 | H20: =Inputs!$C$37 -> 10000000 | I20: =C20-D20-F20+H20 -> 13913940 | J20: =I20*$C$9 -> 437419.89 | K20: =I20*'Borrowing Base'!$C$59 -> 1163753.9 | L20: =I20-J20-K20 -> 12312766 | M20: =L20*0 -> 0 | N20: =I20-M20 -> 13913940 | O20: =L20-M20 -> 12312766 | P20: =$C$10 -> 0.82034993 | Q20: =MIN(Inputs!$C$7,P20*O20*(1-'Borrowing Base'!$C$60)) -> 9826835.6 | R20: =S19 -> 0 | S20: =Q20 -> 9826835.6 | T20: =IF(P20*O20*(1-'Borrowing Base'!$C$60)>Inputs!$C$7,1,0) -> 0 | U20: =R20*(Inputs!$C$9+Inputs!$C$10)/12 -> 0 | V20: =MAX(0,Inputs!$C$7-R20)*Inputs!$C$11/12 -> 16666.667 | W20: =Inputs!$C$38 -> 600000 | X20: =M20*(Inputs!$C$41-Inputs!$C$42) -> 0 | Y20: =Inputs!C49 -> 1600000 | Z20: =AA19 -> 18966894 | AA20: =Z20-H20+F20+G20+E20-U20-V20-W20+(S20-R20)+X20+Y20 -> 19939386 | AB20: =IF(AA20<Inputs!$C$36,1,0) -> 0 | AC20: =AC19+M20*(1-Inputs!$C$41) -> 4808571.7
B21: =B20+1 -> 8 | C21: =N20 -> 13913940 | D21: =C21*$C$8 -> 121630.25 | E21: =D21*(1-Inputs!$C$40) -> 45903.256 | F21: =(C21-D21)*Inputs!$C$39 -> 275846.19 | G21: =(C21-D21)*'Borrowing Base'!$C$9/12 -> 238823.06 | H21: =Inputs!$C$37 -> 10000000 | I21: =C21-D21-F21+H21 -> 23516463 | J21: =I21*$C$9 -> 739299.5 | K21: =I21*'Borrowing Base'!$C$59 -> 1966903.5 | L21: =I21-J21-K21 -> 20810260 | M21: =L21*0 -> 0 | N21: =I21-M21 -> 23516463 | O21: =L21-M21 -> 20810260 | P21: =$C$10 -> 0.82034993 | Q21: =MIN(Inputs!$C$7,P21*O21*(1-'Borrowing Base'!$C$60)) -> 16608698 | R21: =S20 -> 9826835.6 | S21: =Q21 -> 16608698 | T21: =IF(P21*O21*(1-'Borrowing Base'!$C$60)>Inputs!$C$7,1,0) -> 0 | U21: =R21*(Inputs!$C$9+Inputs!$C$10)/12 -> 48560.946 | V21: =MAX(0,Inputs!$C$7-R21)*Inputs!$C$11/12 -> 12572.152 | W21: =Inputs!$C$38 -> 600000 | X21: =M21*(Inputs!$C$41-Inputs!$C$42) -> 0 | Y21: =Inputs!C49 -> 1600000 | Z21: =AA20 -> 19939386 | AA21: =Z21-H21+F21+G21+E21-U21-V21-W21+(S21-R21)+X21+Y21 -> 18220688 | AB21: =IF(AA21<Inputs!$C$36,1,0) -> 0 | AC21: =AC20+M21*(1-Inputs!$C$41) -> 4808571.7
B22: =B21+1 -> 9 | C22: =N21 -> 23516463 | D22: =C22*$C$8 -> 205571.77 | E22: =D22*(1-Inputs!$C$40) -> 77582.787 | F22: =(C22-D22)*Inputs!$C$39 -> 466217.83 | G22: =(C22-D22)*'Borrowing Base'!$C$9/12 -> 403643.67 | H22: =Inputs!$C$37 -> 10000000 | I22: =C22-D22-F22+H22 -> 32844674 | J22: =I22*$C$9 -> 1032555.4 | K22: =I22*'Borrowing Base'!$C$59 -> 2747109.6 | L22: =I22-J22-K22 -> 29065009 | M22: =L22*Inputs!C52 -> 29065009 | N22: =I22-M22 -> 3779665 | O22: =L22-M22 -> 0 | P22: =$C$10 -> 0.82034993 | Q22: =MIN(Inputs!$C$7,P22*O22*(1-'Borrowing Base'!$C$60)) -> 0 | R22: =S21 -> 16608698 | S22: =Q22 -> 0 | T22: =IF(P22*O22*(1-'Borrowing Base'!$C$60)>Inputs!$C$7,1,0) -> 0 | U22: =R22*(Inputs!$C$9+Inputs!$C$10)/12 -> 82074.647 | V22: =MAX(0,Inputs!$C$7-R22)*Inputs!$C$11/12 -> 9746.376 | W22: =Inputs!$C$38 -> 600000 | X22: =M22*(Inputs!$C$41-Inputs!$C$42) -> 27030458 | Y22: =Inputs!C49 -> 1600000 | Z22: =AA21 -> 18220688 | AA22: =Z22-H22+F22+G22+E22-U22-V22-W22+(S22-R22)+X22+Y22 -> 20498072 | AB22: =IF(AA22<Inputs!$C$36,1,0) -> 0 | AC22: =AC21+M22*(1-Inputs!$C$41) -> 6552472.2
B23: =B22+1 -> 10 | C23: =N22 -> 3779665 | D23: =C23*$C$8 -> 33040.361 | E23: =D23*(1-Inputs!$C$40) -> 12469.432 | F23: =(C23-D23)*Inputs!$C$39 -> 74932.493 | G23: =(C23-D23)*'Borrowing Base'!$C$9/12 -> 64875.311 | H23: =Inputs!$C$37 -> 10000000 | I23: =C23-D23-F23+H23 -> 13671692 | J23: =I23*$C$9 -> 429804.22 | K23: =I23*'Borrowing Base'!$C$59 -> 1143492.5 | L23: =I23-J23-K23 -> 12098395 | M23: =L23*0 -> 0 | N23: =I23-M23 -> 13671692 | O23: =L23-M23 -> 12098395 | P23: =$C$10 -> 0.82034993 | Q23: =MIN(Inputs!$C$7,P23*O23*(1-'Borrowing Base'!$C$60)) -> 9655746.2 | R23: =S22 -> 0 | S23: =Q23 -> 9655746.2 | T23: =IF(P23*O23*(1-'Borrowing Base'!$C$60)>Inputs!$C$7,1,0) -> 0 | U23: =R23*(Inputs!$C$9+Inputs!$C$10)/12 -> 0 | V23: =MAX(0,Inputs!$C$7-R23)*Inputs!$C$11/12 -> 16666.667 | W23: =Inputs!$C$38 -> 600000 | X23: =M23*(Inputs!$C$41-Inputs!$C$42) -> 0 | Y23: =Inputs!C49 -> 1600000 | Z23: =AA22 -> 20498072 | AA23: =Z23-H23+F23+G23+E23-U23-V23-W23+(S23-R23)+X23+Y23 -> 21289428 | AB23: =IF(AA23<Inputs!$C$36,1,0) -> 0 | AC23: =AC22+M23*(1-Inputs!$C$41) -> 6552472.2
B24: =B23+1 -> 11 | C24: =N23 -> 13671692 | D24: =C24*$C$8 -> 119512.61 | E24: =D24*(1-Inputs!$C$40) -> 45104.061 | F24: =(C24-D24)*Inputs!$C$39 -> 271043.59 | G24: =(C24-D24)*'Borrowing Base'!$C$9/12 -> 234665.05 | H24: =Inputs!$C$37 -> 10000000 | I24: =C24-D24-F24+H24 -> 23281136 | J24: =I24*$C$9 -> 731901.39 | K24: =I24*'Borrowing Base'!$C$59 -> 1947220.8 | L24: =I24-J24-K24 -> 20602014 | M24: =L24*0 -> 0 | N24: =I24-M24 -> 23281136 | O24: =L24-M24 -> 20602014 | P24: =$C$10 -> 0.82034993 | Q24: =MIN(Inputs!$C$7,P24*O24*(1-'Borrowing Base'!$C$60)) -> 16442496 | R24: =S23 -> 9655746.2 | S24: =Q24 -> 16442496 | T24: =IF(P24*O24*(1-'Borrowing Base'!$C$60)>Inputs!$C$7,1,0) -> 0 | U24: =R24*(Inputs!$C$9+Inputs!$C$10)/12 -> 47715.479 | V24: =MAX(0,Inputs!$C$7-R24)*Inputs!$C$11/12 -> 12643.439 | W24: =Inputs!$C$38 -> 600000 | X24: =M24*(Inputs!$C$41-Inputs!$C$42) -> 0 | Y24: =Inputs!C49 -> 1600000 | Z24: =AA23 -> 21289428 | AA24: =Z24-H24+F24+G24+E24-U24-V24-W24+(S24-R24)+X24+Y24 -> 19566632 | AB24: =IF(AA24<Inputs!$C$36,1,0) -> 0 | AC24: =AC23+M24*(1-Inputs!$C$41) -> 6552472.2
B25: =B24+1 -> 12 | C25: =N24 -> 23281136 | D25: =C25*$C$8 -> 203514.63 | E25: =D25*(1-Inputs!$C$40) -> 76806.423 | F25: =(C25-D25)*Inputs!$C$39 -> 461552.43 | G25: =(C25-D25)*'Borrowing Base'!$C$9/12 -> 399604.44 | H25: =Inputs!$C$37 -> 10000000 | I25: =C25-D25-F25+H25 -> 32616069 | J25: =I25*$C$9 -> 1025368.6 | K25: =I25*'Borrowing Base'!$C$59 -> 2727989.3 | L25: =I25-J25-K25 -> 28862711 | M25: =L25*Inputs!C53 -> 28862711 | N25: =I25-M25 -> 3753357.9 | O25: =L25-M25 -> 0 | P25: =$C$10 -> 0.82034993 | Q25: =MIN(Inputs!$C$7,P25*O25*(1-'Borrowing Base'!$C$60)) -> 0 | R25: =S24 -> 16442496 | S25: =Q25 -> 0 | T25: =IF(P25*O25*(1-'Borrowing Base'!$C$60)>Inputs!$C$7,1,0) -> 0 | U25: =R25*(Inputs!$C$9+Inputs!$C$10)/12 -> 81253.333 | V25: =MAX(0,Inputs!$C$7-R25)*Inputs!$C$11/12 -> 9815.6268 | W25: =Inputs!$C$38 -> 600000 | X25: =M25*(Inputs!$C$41-Inputs!$C$42) -> 26842321 | Y25: =Inputs!C49 -> 1600000 | Z25: =AA24 -> 19566632 | AA25: =Z25-H25+F25+G25+E25-U25-V25-W25+(S25-R25)+X25+Y25 -> 21813352 | AB25: =IF(AA25<Inputs!$C$36,1,0) -> 0 | AC25: =AC24+M25*(1-Inputs!$C$41) -> 8284234.9

Sheet Credit Stress
B2: Credit Stress: 12-Month Liquidity Projection
B3: No manual data entry needed. Month 0 is today.
B5: Scenario Inputs
B6: Metric | C6: Value | D6: Units
B7: Annual default rate | C7: =Inputs!D46 -> 0.2 | D7: %
B8: Monthly default rate: 1 - (1 - annual)^(1/12) | C8: =1-(1-C7)^(1/12) -> 0.01842347 | D8: %
B9: Share more than 60 days late | C9: =Inputs!D47 -> 0.08 | D9: %
B10: Advance rate after any cut | C10: ='Borrowing Base'!$C$48-Inputs!D48 -> 0.72034993 | D10: %
B12: Month | C12: Beginning pool | D12: Defaults | E12: Recoveries | F12: Principal collected | G12: Interest collected | H12: New loans | I12: Pool before sale | J12: Late (ineligible) | K12: Other ineligible | L12: Eligible before sale | M12: Securitized | N12: Ending pool | O12: Eligible after sale | P12: Advance rate | Q12: Borrowing base | R12: Warehouse beginning | S12: Warehouse ending | T12: Facility at limit | U12: Warehouse interest | V12: Unused fee | W12: Operating expenses | X12: Securitization cash | Y12: Cash from past deals | Z12: Beginning cash | AA12: Ending cash | AB12: Covenant breach | AC12: Retained interest
B13: 0 | N13: ='Borrowing Base'!C8 -> 28800314 | S13: =Inputs!$C$8 -> 19500000 | AA13: =Inputs!$C$35 -> 12000000 | AC13: 0
B14: =B13+1 -> 1 | C14: =N13 -> 28800314 | D14: =C14*$C$8 -> 530601.72 | E14: =D14*(1-Inputs!$C$40) -> 200249.09 | F14: =(C14-D14)*Inputs!$C$39 -> 565394.24 | G14: =(C14-D14)*'Borrowing Base'!$C$9/12 -> 489508.96 | H14: =Inputs!$C$37 -> 10000000 | I14: =C14-D14-F14+H14 -> 37704318 | J14: =I14*$C$9 -> 3016345.4 | K14: =I14*'Borrowing Base'!$C$59 -> 3153567.5 | L14: =I14-J14-K14 -> 31534405 | M14: =L14*0 -> 0 | N14: =I14-M14 -> 37704318 | O14: =L14-M14 -> 31534405 | P14: =$C$10 -> 0.72034993 | Q14: =MIN(Inputs!$C$7,P14*O14*(1-'Borrowing Base'!$C$60)) -> 22099735 | R14: =S13 -> 19500000 | S14: =Q14 -> 22099735 | T14: =IF(P14*O14*(1-'Borrowing Base'!$C$60)>Inputs!$C$7,1,0) -> 0 | U14: =R14*(Inputs!$C$9+Inputs!$C$10)/12 -> 96362.5 | V14: =MAX(0,Inputs!$C$7-R14)*Inputs!$C$11/12 -> 8541.6667 | W14: =Inputs!$C$38 -> 600000 | X14: =M14*(Inputs!$C$41-Inputs!$C$42) -> 0 | Y14: =Inputs!D49 -> 800000 | Z14: =AA13 -> 12000000 | AA14: =Z14-H14+F14+G14+E14-U14-V14-W14+(S14-R14)+X14+Y14 -> 5949983.6 | AB14: =IF(AA14<Inputs!$C$36,1,0) -> 0 | AC14: =AC13+M14*(1-Inputs!$C$41) -> 0
B15: =B14+1 -> 2 | C15: =N14 -> 37704318 | D15: =C15*$C$8 -> 694644.37 | E15: =D15*(1-Inputs!$C$40) -> 262158.78 | F15: =(C15-D15)*Inputs!$C$39 -> 740193.46 | G15: =(C15-D15)*'Borrowing Base'!$C$9/12 -> 640847.24 | H15: =Inputs!$C$37 -> 10000000 | I15: =C15-D15-F15+H15 -> 46269480 | J15: =I15*$C$9 -> 3701558.4 | K15: =I15*'Borrowing Base'!$C$59 -> 3869952.7 | L15: =I15-J15-K15 -> 38697969 | M15: =L15*0 -> 0 | N15: =I15-M15 -> 46269480 | O15: =L15-M15 -> 38697969 | P15: =$C$10 -> 0.72034993 | Q15: =MIN(Inputs!$C$7,P15*O15*(1-'Borrowing Base'!$C$60)) -> 27120058 | R15: =S14 -> 22099735 | S15: =Q15 -> 27120058 | T15: =IF(P15*O15*(1-'Borrowing Base'!$C$60)>Inputs!$C$7,1,0) -> 0 | U15: =R15*(Inputs!$C$9+Inputs!$C$10)/12 -> 109209.53 | V15: =MAX(0,Inputs!$C$7-R15)*Inputs!$C$11/12 -> 7458.4436 | W15: =Inputs!$C$38 -> 600000 | X15: =M15*(Inputs!$C$41-Inputs!$C$42) -> 0 | Y15: =Inputs!D49 -> 800000 | Z15: =AA14 -> 5949983.6 | AA15: =Z15-H15+F15+G15+E15-U15-V15-W15+(S15-R15)+X15+Y15 -> 2696837.2 | AB15: =IF(AA15<Inputs!$C$36,1,0) -> 1 | AC15: =AC14+M15*(1-Inputs!$C$41) -> 0
B16: =B15+1 -> 3 | C16: =N15 -> 46269480 | D16: =C16*$C$8 -> 852444.38 | E16: =D16*(1-Inputs!$C$40) -> 321712.51 | F16: =(C16-D16)*Inputs!$C$39 -> 908340.71 | G16: =(C16-D16)*'Borrowing Base'!$C$9/12 -> 786426.34 | H16: =Inputs!$C$37 -> 10000000 | I16: =C16-D16-F16+H16 -> 54508695 | J16: =I16*$C$9 -> 4360695.6 | K16: =I16*'Borrowing Base'!$C$59 -> 4559075.9 | L16: =I16-J16-K16 -> 45588923 | M16: =L16*Inputs!D50 -> 45588923 | N16: =I16-M16 -> 8919771.5 | O16: =L16-M16 -> 0 | P16: =$C$10 -> 0.72034993 | Q16: =MIN(Inputs!$C$7,P16*O16*(1-'Borrowing Base'!$C$60)) -> 0 | R16: =S15 -> 27120058 | S16: =Q16 -> 0 | T16: =IF(P16*O16*(1-'Borrowing Base'!$C$60)>Inputs!$C$7,1,0) -> 0 | U16: =R16*(Inputs!$C$9+Inputs!$C$10)/12 -> 134018.28 | V16: =MAX(0,Inputs!$C$7-R16)*Inputs!$C$11/12 -> 5366.6427 | W16: =Inputs!$C$38 -> 600000 | X16: =M16*(Inputs!$C$41-Inputs!$C$42) -> 42397699 | Y16: =Inputs!D49 -> 800000 | Z16: =AA15 -> 2696837.2 | AA16: =Z16-H16+F16+G16+E16-U16-V16-W16+(S16-R16)+X16+Y16 -> 10051573 | AB16: =IF(AA16<Inputs!$C$36,1,0) -> 0 | AC16: =AC15+M16*(1-Inputs!$C$41) -> 2735335.4
B17: =B16+1 -> 4 | C17: =N16 -> 8919771.5 | D17: =C17*$C$8 -> 164333.14 | E17: =D17*(1-Inputs!$C$40) -> 62019.328 | F17: =(C17-D17)*Inputs!$C$39 -> 175108.77 | G17: =(C17-D17)*'Borrowing Base'!$C$9/12 -> 151606.27 | H17: =Inputs!$C$37 -> 10000000 | I17: =C17-D17-F17+H17 -> 18580330 | J17: =I17*$C$9 -> 1486426.4 | K17: =I17*'Borrowing Base'!$C$59 -> 1554048.1 | L17: =I17-J17-K17 -> 15539855 | M17: =L17*0 -> 0 | N17: =I17-M17 -> 18580330 | O17: =L17-M17 -> 15539855 | P17: =$C$10 -> 0.72034993 | Q17: =MIN(Inputs!$C$7,P17*O17*(1-'Borrowing Base'!$C$60)) -> 10890540 | R17: =S16 -> 0 | S17: =Q17 -> 10890540 | T17: =IF(P17*O17*(1-'Borrowing Base'!$C$60)>Inputs!$C$7,1,0) -> 0 | U17: =R17*(Inputs!$C$9+Inputs!$C$10)/12 -> 0 | V17: =MAX(0,Inputs!$C$7-R17)*Inputs!$C$11/12 -> 16666.667 | W17: =Inputs!$C$38 -> 600000 | X17: =M17*(Inputs!$C$41-Inputs!$C$42) -> 0 | Y17: =Inputs!D49 -> 800000 | Z17: =AA16 -> 10051573 | AA17: =Z17-H17+F17+G17+E17-U17-V17-W17+(S17-R17)+X17+Y17 -> 11514180 | AB17: =IF(AA17<Inputs!$C$36,1,0) -> 0 | AC17: =AC16+M17*(1-Inputs!$C$41) -> 2735335.4
B18: =B17+1 -> 5 | C18: =N17 -> 18580330 | D18: =C18*$C$8 -> 342314.15 | E18: =D18*(1-Inputs!$C$40) -> 129189.36 | F18: =(C18-D18)*Inputs!$C$39 -> 364760.31 | G18: =(C18-D18)*'Borrowing Base'!$C$9/12 -> 315803.43 | H18: =Inputs!$C$37 -> 10000000 | I18: =C18-D18-F18+H18 -> 27873255 | J18: =I18*$C$9 -> 2229860.4 | K18: =I18*'Borrowing Base'!$C$59 -> 2331303 | L18: =I18-J18-K18 -> 23312092 | M18: =L18*0 -> 0 | N18: =I18-M18 -> 27873255 | O18: =L18-M18 -> 23312092 | P18: =$C$10 -> 0.72034993 | Q18: =MIN(Inputs!$C$7,P18*O18*(1-'Borrowing Base'!$C$60)) -> 16337428 | R18: =S17 -> 10890540 | S18: =Q18 -> 16337428 | T18: =IF(P18*O18*(1-'Borrowing Base'!$C$60)>Inputs!$C$7,1,0) -> 0 | U18: =R18*(Inputs!$C$9+Inputs!$C$10)/12 -> 53817.417 | V18: =MAX(0,Inputs!$C$7-R18)*Inputs!$C$11/12 -> 12128.942 | W18: =Inputs!$C$38 -> 600000 | X18: =M18*(Inputs!$C$41-Inputs!$C$42) -> 0 | Y18: =Inputs!D49 -> 800000 | Z18: =AA17 -> 11514180 | AA18: =Z18-H18+F18+G18+E18-U18-V18-W18+(S18-R18)+X18+Y18 -> 7904875 | AB18: =IF(AA18<Inputs!$C$36,1,0) -> 0 | AC18: =AC17+M18*(1-Inputs!$C$41) -> 2735335.4
B19: =B18+1 -> 6 | C19: =N18 -> 27873255 | D19: =C19*$C$8 -> 513522.08 | E19: =D19*(1-Inputs!$C$40) -> 193803.23 | F19: =(C19-D19)*Inputs!$C$39 -> 547194.66 | G19: =(C19-D19)*'Borrowing Base'!$C$9/12 -> 473752.07 | H19: =Inputs!$C$37 -> 10000000 | I19: =C19-D19-F19+H19 -> 36812538 | J19: =I19*$C$9 -> 2945003.1 | K19: =I19*'Borrowing Base'!$C$59 -> 3078979.6 | L19: =I19-J19-K19 -> 30788556 | M19: =L19*Inputs!D51 -> 30788556 | N19: =I19-M19 -> 6023982.6 | O19: =L19-M19 -> 0 | P19: =$C$10 -> 0.72034993 | Q19: =MIN(Inputs!$C$7,P19*O19*(1-'Borrowing Base'!$C$60)) -> 0 | R19: =S18 -> 16337428 | S19: =Q19 -> 0 | T19: =IF(P19*O19*(1-'Borrowing Base'!$C$60)>Inputs!$C$7,1,0) -> 0 | U19: =R19*(Inputs!$C$9+Inputs!$C$10)/12 -> 80734.122 | V19: =MAX(0,Inputs!$C$7-R19)*Inputs!$C$11/12 -> 9859.4051 | W19: =Inputs!$C$38 -> 600000 | X19: =M19*(Inputs!$C$41-Inputs!$C$42) -> 28633357 | Y19: =Inputs!D49 -> 800000 | Z19: =AA18 -> 7904875 | AA19: =Z19-H19+F19+G19+E19-U19-V19-W19+(S19-R19)+X19+Y19 -> 11524961 | AB19: =IF(AA19<Inputs!$C$36,1,0) -> 0 | AC19: =AC18+M19*(1-Inputs!$C$41) -> 4582648.7
B20: =B19+1 -> 7 | C20: =N19 -> 6023982.6 | D20: =C20*$C$8 -> 110982.66 | E20: =D20*(1-Inputs!$C$40) -> 41884.857 | F20: =(C20-D20)*Inputs!$C$39 -> 118260 | G20: =(C20-D20)*'Borrowing Base'!$C$9/12 -> 102387.55 | H20: =Inputs!$C$37 -> 10000000 | I20: =C20-D20-F20+H20 -> 15794740 | J20: =I20*$C$9 -> 1263579.2 | K20: =I20*'Borrowing Base'!$C$59 -> 1321063 | L20: =I20-J20-K20 -> 13210098 | M20: =L20*0 -> 0 | N20: =I20-M20 -> 15794740 | O20: =L20-M20 -> 13210098 | P20: =$C$10 -> 0.72034993 | Q20: =MIN(Inputs!$C$7,P20*O20*(1-'Borrowing Base'!$C$60)) -> 9257814.4 | R20: =S19 -> 0 | S20: =Q20 -> 9257814.4 | T20: =IF(P20*O20*(1-'Borrowing Base'!$C$60)>Inputs!$C$7,1,0) -> 0 | U20: =R20*(Inputs!$C$9+Inputs!$C$10)/12 -> 0 | V20: =MAX(0,Inputs!$C$7-R20)*Inputs!$C$11/12 -> 16666.667 | W20: =Inputs!$C$38 -> 600000 | X20: =M20*(Inputs!$C$41-Inputs!$C$42) -> 0 | Y20: =Inputs!D49 -> 800000 | Z20: =AA19 -> 11524961 | AA20: =Z20-H20+F20+G20+E20-U20-V20-W20+(S20-R20)+X20+Y20 -> 11228641 | AB20: =IF(AA20<Inputs!$C$36,1,0) -> 0 | AC20: =AC19+M20*(1-Inputs!$C$41) -> 4582648.7
B21: =B20+1 -> 8 | C21: =N20 -> 15794740 | D21: =C21*$C$8 -> 290993.92 | E21: =D21*(1-Inputs!$C$40) -> 109821.11 | F21: =(C21-D21)*Inputs!$C$39 -> 310074.92 | G21: =(C21-D21)*'Borrowing Base'!$C$9/12 -> 268457.73 | H21: =Inputs!$C$37 -> 10000000 | I21: =C21-D21-F21+H21 -> 25193671 | J21: =I21*$C$9 -> 2015493.7 | K21: =I21*'Borrowing Base'!$C$59 -> 2107184.2 | L21: =I21-J21-K21 -> 21070993 | M21: =L21*0 -> 0 | N21: =I21-M21 -> 25193671 | O21: =L21-M21 -> 21070993 | P21: =$C$10 -> 0.72034993 | Q21: =MIN(Inputs!$C$7,P21*O21*(1-'Borrowing Base'!$C$60)) -> 14766836 | R21: =S20 -> 9257814.4 | S21: =Q21 -> 14766836 | T21: =IF(P21*O21*(1-'Borrowing Base'!$C$60)>Inputs!$C$7,1,0) -> 0 | U21: =R21*(Inputs!$C$9+Inputs!$C$10)/12 -> 45749.033 | V21: =MAX(0,Inputs!$C$7-R21)*Inputs!$C$11/12 -> 12809.244 | W21: =Inputs!$C$38 -> 600000 | X21: =M21*(Inputs!$C$41-Inputs!$C$42) -> 0 | Y21: =Inputs!D49 -> 800000 | Z21: =AA20 -> 11228641 | AA21: =Z21-H21+F21+G21+E21-U21-V21-W21+(S21-R21)+X21+Y21 -> 7567457.6 | AB21: =IF(AA21<Inputs!$C$36,1,0) -> 0 | AC21: =AC20+M21*(1-Inputs!$C$41) -> 4582648.7
B22: =B21+1 -> 9 | C22: =N21 -> 25193671 | D22: =C22*$C$8 -> 464154.85 | E22: =D22*(1-Inputs!$C$40) -> 175172.04 | F22: =(C22-D22)*Inputs!$C$39 -> 494590.33 | G22: =(C22-D22)*'Borrowing Base'!$C$9/12 -> 428208.11 | H22: =Inputs!$C$37 -> 10000000 | I22: =C22-D22-F22+H22 -> 34234926 | J22: =I22*$C$9 -> 2738794.1 | K22: =I22*'Borrowing Base'!$C$59 -> 2863389.5 | L22: =I22-J22-K22 -> 28632742 | M22: =L22*Inputs!D52 -> 28632742 | N22: =I22-M22 -> 5602183.6 | O22: =L22-M22 -> 0 | P22: =$C$10 -> 0.72034993 | Q22: =MIN(Inputs!$C$7,P22*O22*(1-'Borrowing Base'!$C$60)) -> 0 | R22: =S21 -> 14766836 | S22: =Q22 -> 0 | T22: =IF(P22*O22*(1-'Borrowing Base'!$C$60)>Inputs!$C$7,1,0) -> 0 | U22: =R22*(Inputs!$C$9+Inputs!$C$10)/12 -> 72972.78 | V22: =MAX(0,Inputs!$C$7-R22)*Inputs!$C$11/12 -> 10513.818 | W22: =Inputs!$C$38 -> 600000 | X22: =M22*(Inputs!$C$41-Inputs!$C$42) -> 26628450 | Y22: =Inputs!D49 -> 800000 | Z22: =AA21 -> 7567457.6 | AA22: =Z22-H22+F22+G22+E22-U22-V22-W22+(S22-R22)+X22+Y22 -> 10643556 | AB22: =IF(AA22<Inputs!$C$36,1,0) -> 0 | AC22: =AC21+M22*(1-Inputs!$C$41) -> 6300613.3
B23: =B22+1 -> 10 | C23: =N22 -> 5602183.6 | D23: =C23*$C$8 -> 103211.66 | E23: =D23*(1-Inputs!$C$40) -> 38952.081 | F23: =(C23-D23)*Inputs!$C$39 -> 109979.44 | G23: =(C23-D23)*'Borrowing Base'!$C$9/12 -> 95218.376 | H23: =Inputs!$C$37 -> 10000000 | I23: =C23-D23-F23+H23 -> 15388993 | J23: =I23*$C$9 -> 1231119.4 | K23: =I23*'Borrowing Base'!$C$59 -> 1287126.5 | L23: =I23-J23-K23 -> 12870747 | M23: =L23*0 -> 0 | N23: =I23-M23 -> 15388993 | O23: =L23-M23 -> 12870747 | P23: =$C$10 -> 0.72034993 | Q23: =MIN(Inputs!$C$7,P23*O23*(1-'Borrowing Base'!$C$60)) -> 9019992.5 | R23: =S22 -> 0 | S23: =Q23 -> 9019992.5 | T23: =IF(P23*O23*(1-'Borrowing Base'!$C$60)>Inputs!$C$7,1,0) -> 0 | U23: =R23*(Inputs!$C$9+Inputs!$C$10)/12 -> 0 | V23: =MAX(0,Inputs!$C$7-R23)*Inputs!$C$11/12 -> 16666.667 | W23: =Inputs!$C$38 -> 600000 | X23: =M23*(Inputs!$C$41-Inputs!$C$42) -> 0 | Y23: =Inputs!D49 -> 800000 | Z23: =AA22 -> 10643556 | AA23: =Z23-H23+F23+G23+E23-U23-V23-W23+(S23-R23)+X23+Y23 -> 10091032 | AB23: =IF(AA23<Inputs!$C$36,1,0) -> 0 | AC23: =AC22+M23*(1-Inputs!$C$41) -> 6300613.3
B24: =B23+1 -> 11 | C24: =N23 -> 15388993 | D24: =C24*$C$8 -> 283518.64 | E24: =D24*(1-Inputs!$C$40) -> 106999.94 | F24: =(C24-D24)*Inputs!$C$39 -> 302109.48 | G24: =(C24-D24)*'Borrowing Base'!$C$9/12 -> 261561.38 | H24: =Inputs!$C$37 -> 10000000 | I24: =C24-D24-F24+H24 -> 24803364 | J24: =I24*$C$9 -> 1984269.2 | K24: =I24*'Borrowing Base'!$C$59 -> 2074539.1 | L24: =I24-J24-K24 -> 20744556 | M24: =L24*0 -> 0 | N24: =I24-M24 -> 24803364 | O24: =L24-M24 -> 20744556 | P24: =$C$10 -> 0.72034993 | Q24: =MIN(Inputs!$C$7,P24*O24*(1-'Borrowing Base'!$C$60)) -> 14538064 | R24: =S23 -> 9019992.5 | S24: =Q24 -> 14538064 | T24: =IF(P24*O24*(1-'Borrowing Base'!$C$60)>Inputs!$C$7,1,0) -> 0 | U24: =R24*(Inputs!$C$9+Inputs!$C$10)/12 -> 44573.796 | V24: =MAX(0,Inputs!$C$7-R24)*Inputs!$C$11/12 -> 12908.336 | W24: =Inputs!$C$38 -> 600000 | X24: =M24*(Inputs!$C$41-Inputs!$C$42) -> 0 | Y24: =Inputs!D49 -> 800000 | Z24: =AA23 -> 10091032 | AA24: =Z24-H24+F24+G24+E24-U24-V24-W24+(S24-R24)+X24+Y24 -> 6422292.1 | AB24: =IF(AA24<Inputs!$C$36,1,0) -> 0 | AC24: =AC23+M24*(1-Inputs!$C$41) -> 6300613.3
B25: =B24+1 -> 12 | C25: =N24 -> 24803364 | D25: =C25*$C$8 -> 456964.04 | E25: =D25*(1-Inputs!$C$40) -> 172458.23 | F25: =(C25-D25)*Inputs!$C$39 -> 486928.01 | G25: =(C25-D25)*'Borrowing Base'!$C$9/12 -> 421574.2 | H25: =Inputs!$C$37 -> 10000000 | I25: =C25-D25-F25+H25 -> 33859472 | J25: =I25*$C$9 -> 2708757.8 | K25: =I25*'Borrowing Base'!$C$59 -> 2831986.8 | L25: =I25-J25-K25 -> 28318728 | M25: =L25*Inputs!D53 -> 28318728 | N25: =I25-M25 -> 5540744.6 | O25: =L25-M25 -> 0 | P25: =$C$10 -> 0.72034993 | Q25: =MIN(Inputs!$C$7,P25*O25*(1-'Borrowing Base'!$C$60)) -> 0 | R25: =S24 -> 14538064 | S25: =Q25 -> 0 | T25: =IF(P25*O25*(1-'Borrowing Base'!$C$60)>Inputs!$C$7,1,0) -> 0 | U25: =R25*(Inputs!$C$9+Inputs!$C$10)/12 -> 71842.268 | V25: =MAX(0,Inputs!$C$7-R25)*Inputs!$C$11/12 -> 10609.14 | W25: =Inputs!$C$38 -> 600000 | X25: =M25*(Inputs!$C$41-Inputs!$C$42) -> 26336417 | Y25: =Inputs!D49 -> 800000 | Z25: =AA24 -> 6422292.1 | AA25: =Z25-H25+F25+G25+E25-U25-V25-W25+(S25-R25)+X25+Y25 -> 9419153.7 | AB25: =IF(AA25<Inputs!$C$36,1,0) -> 0 | AC25: =AC24+M25*(1-Inputs!$C$41) -> 7999736.9

Sheet Market Freeze
B2: Market Freeze: 12-Month Liquidity Projection
B3: No manual data entry needed. Month 0 is today.
B5: Scenario Inputs
B6: Metric | C6: Value | D6: Units
B7: Annual default rate | C7: =Inputs!E46 -> 0.1 | D7: %
B8: Monthly default rate: 1 - (1 - annual)^(1/12) | C8: =1-(1-C7)^(1/12) -> 0.008741611 | D8: %
B9: Share more than 60 days late | C9: =Inputs!E47 -> 0.031437529 | D9: %
B10: Advance rate after any cut | C10: ='Borrowing Base'!$C$48-Inputs!E48 -> 0.82034993 | D10: %
B12: Month | C12: Beginning pool | D12: Defaults | E12: Recoveries | F12: Principal collected | G12: Interest collected | H12: New loans | I12: Pool before sale | J12: Late (ineligible) | K12: Other ineligible | L12: Eligible before sale | M12: Securitized | N12: Ending pool | O12: Eligible after sale | P12: Advance rate | Q12: Borrowing base | R12: Warehouse beginning | S12: Warehouse ending | T12: Facility at limit | U12: Warehouse interest | V12: Unused fee | W12: Operating expenses | X12: Securitization cash | Y12: Cash from past deals | Z12: Beginning cash | AA12: Ending cash | AB12: Covenant breach | AC12: Retained interest
B13: 0 | N13: ='Borrowing Base'!C8 -> 28800314 | S13: =Inputs!$C$8 -> 19500000 | AA13: =Inputs!$C$35 -> 12000000 | AC13: 0
B14: =B13+1 -> 1 | C14: =N13 -> 28800314 | D14: =C14*$C$8 -> 251761.14 | E14: =D14*(1-Inputs!$C$40) -> 95014.653 | F14: =(C14-D14)*Inputs!$C$39 -> 570971.05 | G14: =(C14-D14)*'Borrowing Base'!$C$9/12 -> 494337.27 | H14: =Inputs!$C$37 -> 10000000 | I14: =C14-D14-F14+H14 -> 37977581 | J14: =I14*$C$9 -> 1193921.3 | K14: =I14*'Borrowing Base'!$C$59 -> 3176423.1 | L14: =I14-J14-K14 -> 33607237 | M14: =L14*0 -> 0 | N14: =I14-M14 -> 37977581 | O14: =L14-M14 -> 33607237 | P14: =$C$10 -> 0.82034993 | Q14: =MIN(Inputs!$C$7,P14*O14*(1-'Borrowing Base'!$C$60)) -> 26821982 | R14: =S13 -> 19500000 | S14: =Q14 -> 26821982 | T14: =IF(P14*O14*(1-'Borrowing Base'!$C$60)>Inputs!$C$7,1,0) -> 0 | U14: =R14*(Inputs!$C$9+Inputs!$C$10)/12 -> 96362.5 | V14: =MAX(0,Inputs!$C$7-R14)*Inputs!$C$11/12 -> 8541.6667 | W14: =Inputs!$C$38 -> 600000 | X14: =M14*(Inputs!$C$41-Inputs!$C$42) -> 0 | Y14: =Inputs!E49 -> 1600000 | Z14: =AA13 -> 12000000 | AA14: =Z14-H14+F14+G14+E14-U14-V14-W14+(S14-R14)+X14+Y14 -> 11377401 | AB14: =IF(AA14<Inputs!$C$36,1,0) -> 0 | AC14: =AC13+M14*(1-Inputs!$C$41) -> 0
B15: =B14+1 -> 2 | C15: =N14 -> 37977581 | D15: =C15*$C$8 -> 331985.24 | E15: =D15*(1-Inputs!$C$40) -> 125291.23 | F15: =(C15-D15)*Inputs!$C$39 -> 752911.92 | G15: =(C15-D15)*'Borrowing Base'!$C$9/12 -> 651858.67 | H15: =Inputs!$C$37 -> 10000000 | I15: =C15-D15-F15+H15 -> 46892684 | J15: =I15*$C$9 -> 1474190.1 | K15: =I15*'Borrowing Base'!$C$59 -> 3922077.2 | L15: =I15-J15-K15 -> 41496417 | M15: =L15*0 -> 0 | N15: =I15-M15 -> 46892684 | O15: =L15-M15 -> 41496417 | P15: =$C$10 -> 0.82034993 | Q15: =MIN(Inputs!$C$7,P15*O15*(1-'Borrowing Base'!$C$60)) -> 33118348 | R15: =S14 -> 26821982 | S15: =Q15 -> 33118348 | T15: =IF(P15*O15*(1-'Borrowing Base'!$C$60)>Inputs!$C$7,1,0) -> 0 | U15: =R15*(Inputs!$C$9+Inputs!$C$10)/12 -> 132545.3 | V15: =MAX(0,Inputs!$C$7-R15)*Inputs!$C$11/12 -> 5490.8407 | W15: =Inputs!$C$38 -> 600000 | X15: =M15*(Inputs!$C$41-Inputs!$C$42) -> 0 | Y15: =Inputs!E49 -> 1600000 | Z15: =AA14 -> 11377401 | AA15: =Z15-H15+F15+G15+E15-U15-V15-W15+(S15-R15)+X15+Y15 -> 10065792 | AB15: =IF(AA15<Inputs!$C$36,1,0) -> 0 | AC15: =AC14+M15*(1-Inputs!$C$41) -> 0
B16: =B15+1 -> 3 | C16: =N15 -> 46892684 | D16: =C16*$C$8 -> 409917.6 | E16: =D16*(1-Inputs!$C$40) -> 154702.9 | F16: =(C16-D16)*Inputs!$C$39 -> 929655.33 | G16: =(C16-D16)*'Borrowing Base'!$C$9/12 -> 804880.18 | H16: =Inputs!$C$37 -> 10000000 | I16: =C16-D16-F16+H16 -> 55553111 | J16: =I16*$C$9 -> 1746452.6 | K16: =I16*'Borrowing Base'!$C$59 -> 4646430.3 | L16: =I16-J16-K16 -> 49160228 | M16: =L16*Inputs!E50 -> 0 | N16: =I16-M16 -> 55553111 | O16: =L16-M16 -> 49160228 | P16: =$C$10 -> 0.82034993 | Q16: =MIN(Inputs!$C$7,P16*O16*(1-'Borrowing Base'!$C$60)) -> 39234846 | R16: =S15 -> 33118348 | S16: =Q16 -> 39234846 | T16: =IF(P16*O16*(1-'Borrowing Base'!$C$60)>Inputs!$C$7,1,0) -> 0 | U16: =R16*(Inputs!$C$9+Inputs!$C$10)/12 -> 163659.84 | V16: =MAX(0,Inputs!$C$7-R16)*Inputs!$C$11/12 -> 2867.3551 | W16: =Inputs!$C$38 -> 600000 | X16: =M16*(Inputs!$C$41-Inputs!$C$42) -> 0 | Y16: =Inputs!E49 -> 1600000 | Z16: =AA15 -> 10065792 | AA16: =Z16-H16+F16+G16+E16-U16-V16-W16+(S16-R16)+X16+Y16 -> 8905002.1 | AB16: =IF(AA16<Inputs!$C$36,1,0) -> 0 | AC16: =AC15+M16*(1-Inputs!$C$41) -> 0
B17: =B16+1 -> 4 | C17: =N16 -> 55553111 | D17: =C17*$C$8 -> 485623.69 | E17: =D17*(1-Inputs!$C$40) -> 183274.38 | F17: =(C17-D17)*Inputs!$C$39 -> 1101349.8 | G17: =(C17-D17)*'Borrowing Base'!$C$9/12 -> 953530.37 | H17: =Inputs!$C$37 -> 10000000 | I17: =C17-D17-F17+H17 -> 63966138 | J17: =I17*$C$9 -> 2010937.3 | K17: =I17*'Borrowing Base'!$C$59 -> 5350091 | L17: =I17-J17-K17 -> 56605109 | M17: =L17*0 -> 0 | N17: =I17-M17 -> 63966138 | O17: =L17-M17 -> 56605109 | P17: =$C$10 -> 0.82034993 | Q17: =MIN(Inputs!$C$7,P17*O17*(1-'Borrowing Base'!$C$60)) -> 40000000 | R17: =S16 -> 39234846 | S17: =Q17 -> 40000000 | T17: =IF(P17*O17*(1-'Borrowing Base'!$C$60)>Inputs!$C$7,1,0) -> 1 | U17: =R17*(Inputs!$C$9+Inputs!$C$10)/12 -> 193885.53 | V17: =MAX(0,Inputs!$C$7-R17)*Inputs!$C$11/12 -> 318.81399 | W17: =Inputs!$C$38 -> 600000 | X17: =M17*(Inputs!$C$41-Inputs!$C$42) -> 0 | Y17: =Inputs!E49 -> 1600000 | Z17: =AA16 -> 8905002.1 | AA17: =Z17-H17+F17+G17+E17-U17-V17-W17+(S17-R17)+X17+Y17 -> 2714105.9 | AB17: =IF(AA17<Inputs!$C$36,1,0) -> 1 | AC17: =AC16+M17*(1-Inputs!$C$41) -> 0
B18: =B17+1 -> 5 | C18: =N17 -> 63966138 | D18: =C18*$C$8 -> 559167.09 | E18: =D18*(1-Inputs!$C$40) -> 211029.66 | F18: =(C18-D18)*Inputs!$C$39 -> 1268139.4 | G18: =(C18-D18)*'Borrowing Base'!$C$9/12 -> 1097934.1 | H18: =Inputs!$C$37 -> 10000000 | I18: =C18-D18-F18+H18 -> 72138831 | J18: =I18*$C$9 -> 2267866.6 | K18: =I18*'Borrowing Base'!$C$59 -> 6033650.4 | L18: =I18-J18-K18 -> 63837314 | M18: =L18*0 -> 0 | N18: =I18-M18 -> 72138831 | O18: =L18-M18 -> 63837314 | P18: =$C$10 -> 0.82034993 | Q18: =MIN(Inputs!$C$7,P18*O18*(1-'Borrowing Base'!$C$60)) -> 40000000 | R18: =S17 -> 40000000 | S18: =Q18 -> 40000000 | T18: =IF(P18*O18*(1-'Borrowing Base'!$C$60)>Inputs!$C$7,1,0) -> 1 | U18: =R18*(Inputs!$C$9+Inputs!$C$10)/12 -> 197666.67 | V18: =MAX(0,Inputs!$C$7-R18)*Inputs!$C$11/12 -> 0 | W18: =Inputs!$C$38 -> 600000 | X18: =M18*(Inputs!$C$41-Inputs!$C$42) -> 0 | Y18: =Inputs!E49 -> 1600000 | Z18: =AA17 -> 2714105.9 | AA18: =Z18-H18+F18+G18+E18-U18-V18-W18+(S18-R18)+X18+Y18 -> -3906457.6 | AB18: =IF(AA18<Inputs!$C$36,1,0) -> 1 | AC18: =AC17+M18*(1-Inputs!$C$41) -> 0
B19: =B18+1 -> 6 | C19: =N18 -> 72138831 | D19: =C19*$C$8 -> 630609.6 | E19: =D19*(1-Inputs!$C$40) -> 237992.06 | F19: =(C19-D19)*Inputs!$C$39 -> 1430164.4 | G19: =(C19-D19)*'Borrowing Base'!$C$9/12 -> 1238212.7 | H19: =Inputs!$C$37 -> 10000000 | I19: =C19-D19-F19+H19 -> 80078057 | J19: =I19*$C$9 -> 2517456.3 | K19: =I19*'Borrowing Base'!$C$59 -> 6697682.7 | L19: =I19-J19-K19 -> 70862918 | M19: =L19*Inputs!E51 -> 0 | N19: =I19-M19 -> 80078057 | O19: =L19-M19 -> 70862918 | P19: =$C$10 -> 0.82034993 | Q19: =MIN(Inputs!$C$7,P19*O19*(1-'Borrowing Base'!$C$60)) -> 40000000 | R19: =S18 -> 40000000 | S19: =Q19 -> 40000000 | T19: =IF(P19*O19*(1-'Borrowing Base'!$C$60)>Inputs!$C$7,1,0) -> 1 | U19: =R19*(Inputs!$C$9+Inputs!$C$10)/12 -> 197666.67 | V19: =MAX(0,Inputs!$C$7-R19)*Inputs!$C$11/12 -> 0 | W19: =Inputs!$C$38 -> 600000 | X19: =M19*(Inputs!$C$41-Inputs!$C$42) -> 0 | Y19: =Inputs!E49 -> 1600000 | Z19: =AA18 -> -3906457.6 | AA19: =Z19-H19+F19+G19+E19-U19-V19-W19+(S19-R19)+X19+Y19 -> -10197755 | AB19: =IF(AA19<Inputs!$C$36,1,0) -> 1 | AC19: =AC18+M19*(1-Inputs!$C$41) -> 0
B20: =B19+1 -> 7 | C20: =N19 -> 80078057 | D20: =C20*$C$8 -> 700011.22 | E20: =D20*(1-Inputs!$C$40) -> 264184.24 | F20: =(C20-D20)*Inputs!$C$39 -> 1587560.9 | G20: =(C20-D20)*'Borrowing Base'!$C$9/12 -> 1374483.9 | H20: =Inputs!$C$37 -> 10000000 | I20: =C20-D20-F20+H20 -> 87790485 | J20: =I20*$C$9 -> 2759915.9 | K20: =I20*'Borrowing Base'!$C$59 -> 7342745.7 | L20: =I20-J20-K20 -> 77687823 | M20: =L20*0 -> 0 | N20: =I20-M20 -> 87790485 | O20: =L20-M20 -> 77687823 | P20: =$C$10 -> 0.82034993 | Q20: =MIN(Inputs!$C$7,P20*O20*(1-'Borrowing Base'!$C$60)) -> 40000000 | R20: =S19 -> 40000000 | S20: =Q20 -> 40000000 | T20: =IF(P20*O20*(1-'Borrowing Base'!$C$60)>Inputs!$C$7,1,0) -> 1 | U20: =R20*(Inputs!$C$9+Inputs!$C$10)/12 -> 197666.67 | V20: =MAX(0,Inputs!$C$7-R20)*Inputs!$C$11/12 -> 0 | W20: =Inputs!$C$38 -> 600000 | X20: =M20*(Inputs!$C$41-Inputs!$C$42) -> 0 | Y20: =Inputs!E49 -> 1600000 | Z20: =AA19 -> -10197755 | AA20: =Z20-H20+F20+G20+E20-U20-V20-W20+(S20-R20)+X20+Y20 -> -16169193 | AB20: =IF(AA20<Inputs!$C$36,1,0) -> 1 | AC20: =AC19+M20*(1-Inputs!$C$41) -> 0
B21: =B20+1 -> 8 | C21: =N20 -> 87790485 | D21: =C21*$C$8 -> 767430.27 | E21: =D21*(1-Inputs!$C$40) -> 289628.18 | F21: =(C21-D21)*Inputs!$C$39 -> 1740461.1 | G21: =(C21-D21)*'Borrowing Base'!$C$9/12 -> 1506862.4 | H21: =Inputs!$C$37 -> 10000000 | I21: =C21-D21-F21+H21 -> 95282594 | J21: =I21*$C$9 -> 2995449.3 | K21: =I21*'Borrowing Base'!$C$59 -> 7969381.4 | L21: =I21-J21-K21 -> 84317763 | M21: =L21*0 -> 0 | N21: =I21-M21 -> 95282594 | O21: =L21-M21 -> 84317763 | P21: =$C$10 -> 0.82034993 | Q21: =MIN(Inputs!$C$7,P21*O21*(1-'Borrowing Base'!$C$60)) -> 40000000 | R21: =S20 -> 40000000 | S21: =Q21 -> 40000000 | T21: =IF(P21*O21*(1-'Borrowing Base'!$C$60)>Inputs!$C$7,1,0) -> 1 | U21: =R21*(Inputs!$C$9+Inputs!$C$10)/12 -> 197666.67 | V21: =MAX(0,Inputs!$C$7-R21)*Inputs!$C$11/12 -> 0 | W21: =Inputs!$C$38 -> 600000 | X21: =M21*(Inputs!$C$41-Inputs!$C$42) -> 0 | Y21: =Inputs!E49 -> 1600000 | Z21: =AA20 -> -16169193 | AA21: =Z21-H21+F21+G21+E21-U21-V21-W21+(S21-R21)+X21+Y21 -> -21829908 | AB21: =IF(AA21<Inputs!$C$36,1,0) -> 1 | AC21: =AC20+M21*(1-Inputs!$C$41) -> 0
